<?xml version="1.0"?>
<robot name="robot">

<mujoco>
   <compiler meshdir="meshes/" balanceinertia="true"/>
</mujoco>

  <material name="Azure">
    <color rgba="0.94 1 1 1"/>
  </material>
  <material name="Honeydew">
    <color rgba="0.94 1 0.14 1"/>
  </material>
  <material name="white">
    <color rgba="1 1 1 1"/>
  </material>
  <material name="lvory">
  <color rgba="1 1 0.941187 1.0"/>
  </material>

  <!-- Used for fixing robot to Gazebo 'base_link' -->

  <link name="world"/>
  <joint name="fixed" type="fixed">
    <parent link="world"/>
    <child link="base"/>
    <origin rpy="0 0 0" xyz="0 0 0.5"/>
  </joint>

<!--instrument manipulator arm 1  -->

  <link name="base">
    <visual>
      <geometry>
        <mesh filename="package://base.stl"/>
      </geometry>
      <material name="lvory"/>
    </visual>
    <collision>
      <geometry>
        <mesh filename="package://base.stl"/>
      </geometry>
    </collision>
  </link>

  <joint name="roll1" type="revolute">
    <limit effort="1000.0" lower="-3" upper="3" velocity="3.14"/>
    <axis xyz="0 0 1"/>
    <parent link="base"/>
    <child link="roll1"/>
    <origin rpy="0 2.0943951 0" xyz="0.1862 0 -0.1475"/>
    <dynamics damping="0.1" friction="0.05"/>
  </joint>

    <link name="roll1">
      <visual>
        <geometry>
          <mesh filename="package://roll1.stl"/>
        </geometry>
        <material name="Azure"/>
      </visual>
      <collision>
        <geometry>
          <mesh filename="package://roll1.stl"/>
        </geometry>
      </collision>
    </link>

    <joint name="roll2" type="revolute">
      <limit effort="1000.0" lower="-3" upper="3" velocity="3.14"/>
      <axis xyz="0 0 1"/>
      <parent link="roll1"/>
      <child link="roll2"/>
      <origin rpy="0 -0.261799 0" xyz="0.15587 0 0.155"/>
      <dynamics damping="0.1" friction="0.05"/>
    </joint>
<!--    <origin rpy="0 0.261799 0" xyz="0.17 0 -0.11296"/>  -->

      <link name="roll2">
        <visual>
          <geometry>
            <mesh filename="package://roll2.stl"/>
          </geometry>
          <material name="Honeydew"/>
        </visual>
        <collision>
          <geometry>
            <mesh filename="package://roll2.stl"/>
          </geometry>
        </collision>
      </link>

    <joint name="link1" type="revolute">
      <limit effort="1000.0" lower="-3" upper="3" velocity="3.14"/>
      <axis xyz="0 0 1"/>
      <parent link="roll2"/>
      <child link="link1"/>
      <origin rpy="-1.570796 -1.745329 0" xyz="0.06078 -0.029 0.25714"/>
      <dynamics damping="0.1" friction="0.05"/>
    </joint>
    <!--    <origin rpy="0 0.261799 0" xyz="0.17 0 -0.11296"/>  -->

      <link name="link1">
        <visual>
          <geometry>
            <mesh filename="package://link1.stl"/>
          </geometry>
          <material name="Azure"/>
        </visual>
        <collision>
          <geometry>
            <mesh filename="package://link1.stl"/>
          </geometry>
        </collision>
      </link>

    <joint name="link2" type="revolute">
      <limit effort="1000.0" lower="-3" upper="3" velocity="3.14"/>
      <axis xyz="0 0 1"/>
      <parent link="link1"/>
      <child link="link2"/>
      <origin rpy="0 0 0" xyz="-0.2 0 -0.071"/>
      <dynamics damping="0.1" friction="0.05"/>
    </joint>
    <!--    <origin rpy="0 0.261799 0" xyz="0.17 0 -0.11296"/>  -->

      <link name="link2">
        <visual>
          <geometry>
            <mesh filename="package://link2.stl"/>
          </geometry>
          <material name="Azure"/>
        </visual>
        <collision>
          <geometry>
            <mesh filename="package://link2.stl"/>
          </geometry>
        </collision>
      </link>

    <joint name="link3" type="revolute">
      <limit effort="1000.0" lower="-3" upper="3" velocity="3.14"/>
      <axis xyz="0 0 1"/>
      <parent link="link2"/>
      <child link="link3"/>
      <origin rpy="0 0 0.61115" xyz="0.35 0 0.077"/>
      <dynamics damping="0.1" friction="0.05"/>
    </joint>
    <!--    <origin rpy="0 0.261799 0" xyz="0.17 0 -0.11296"/>  -->

      <link name="link3">
        <visual>
          <geometry>
            <mesh filename="package://link3.stl"/>
          </geometry>
          <material name="Azure"/>
        </visual>
        <collision>
          <geometry>
            <mesh filename="package://link3.stl"/>
          </geometry>
        </collision>
      </link>
</robot>




























