<!--
MODEL : A 6 DOF robot with coupled degrees of freedom
mujoco::Advanced physics simulation engine
Version:1.50
-->

<mujoco model="robot">

    <compiler angle="radian" inertiafromgeom="true" meshdir="meshes/" />
    <option timestep="0.002"/>
    <size nuser_actuator="5"/>

    <asset>
    <mesh name="base_3_col"      file="collision/base_3.stl"/>
    <mesh name="base_4_col"      file="collision/base_4.stl"/>
    <mesh name="roll1_col"       file="collision/roll1.stl"/>
    <mesh name="roll2_col"       file="collision/roll2.stl"/>
    <mesh name="para2_col"       file="collision/para2.stl"/>
    <mesh name="para3_col"       file="collision/para3.stl"/>
    <mesh name="slide_col"       file="collision/slide.stl"/>
    <mesh name="instrument_col"  file="collision/instrument.stl"/>
    <mesh name="endoscope_col"   file="collision/endoscope.stl"/>
    <mesh name="rotate_col"      file="collision/rotate.stl"/>
    <mesh name="roll_col"        file="collision/roll.stl"/>
    <mesh name="clip1_col"       file="collision/clip.stl"/>
    <mesh name="clip2_col"       file="collision/clip.stl"/>
    <mesh name="bone_part_col"   file="collision/bone_part.stl"/>
    <mesh name="base_0_col"      file="collision/base_0.stl"/>
    <mesh name="base_1_col"      file="collision/base_1.stl"/>
    <mesh name="bed_col"        file="collision/bed.stl"/>

    <mesh name="base_3_viz"      file="visual/base_3.stl"/>
    <mesh name="base_4_viz"      file="visual/base_4.stl"/>
    <mesh name="roll1_viz"       file="visual/roll1.stl"/>
    <mesh name="roll2_viz"       file="visual/roll2.stl"/>
    <mesh name="para2_viz"       file="visual/para2.stl"/>
    <mesh name="para3_viz"       file="visual/para3.stl"/>
    <mesh name="slide_viz"       file="visual/slide.stl"/>
    <mesh name="instrument_viz"  file="visual/instrument.stl"/>
    <mesh name="endoscope_viz"   file="visual/endoscope.stl"/>
    <mesh name="rotate_viz"      file="visual/rotate.stl"/>
    <mesh name="roll_viz"        file="visual/roll.stl"/>
    <mesh name="clip1_viz"       file="visual/clip.stl"/>
    <mesh name="clip2_viz"       file="visual/clip.stl"/>
    <mesh name="bone_part_viz"   file="visual/bone_part.stl"/>
    <mesh name="base_0_viz"      file="visual/base_0.stl"/>
    <mesh name="base_1_viz"      file="visual/base_1.stl"/>
    <mesh name="bed_viz"        file="visual/bed.stl"/>

        <texture name="floor_tex"   type="2d"       builtin="checker"  rgb1=".2 .3 .4" rgb2=".1 .2 .3" width="100" height="100" />
        <texture name="sky_tex"     type="skybox"   builtin="gradient" width="100"     height="100"    rgb1="1 1 1" rgb2="0.3 0.3 0.8" />

        <material name='floor_mat'      texture="floor_tex"  shininess="0.8" texrepeat="10 10" specular="0.7"  reflectance="0.5" />
    </asset>

    <visual>
        <map fogstart="3" fogend="5" znear="0.05"/>
        <quality shadowsize="4096"/>
        <scale framelength="0.1"
               framewidth="0.005"
               contactwidth="0.1"
               contactheight="0.005"
               forcewidth="0.01"
               />
    </visual>

    <default>
        <default class="panda">
            <joint pos="0 0 0" axis="0 0 1" limited="true"/>
            <position forcelimited="true" ctrllimited="true" user="1002 40 2001 -0.005 0.005"/>
            <default class="panda_viz">
                <geom contype="0" conaffinity="0" group="0" type="mesh" rgba=".95 .99 .92 1" mass="0"/>
            </default>

            <default class="panda_col">
                <geom contype="1" conaffinity="1" group="3" type="mesh" rgba=".5 .6 .7 1"/>
            </default>

            <default class="panda_arm">
                <joint damping="100"/>
            </default>
             <default class="panda_forearm">
                <joint damping="10"/>
            </default>
             <default class="panda_finger">
                <joint damping="10" armature='5'/>
                <geom friction="1 0.5 0.0001" solref="0.01 1" solimp="0.8 0.9 0.001" margin="0.001" user="0" rgba="0.5 0.6 0.7 .4" contype="1" conaffinity="0" condim="6" group="3" />
                <position user="1002 40 2001 -0.0001 0.0001"/>
            </default>
        </default>
    </default>
    <!--Contacts-->
    <contact>
        <exclude body1="clip1" body2="bone"/>
        <exclude body1="clip2" body2="bone"/>
        <exclude body1="roll" body2="bone"/>
        <exclude body1="rotate" body2="bone"/>
        <exclude body1="instrument" body2="bone"/>
        <exclude body1="clip1_dual" body2="bone"/>
        <exclude body1="clip2_dual" body2="bone"/>
        <exclude body1="roll_dual" body2="bone"/>
        <exclude body1="rotate_dual" body2="bone"/>
        <exclude body1="instrument_dual" body2="bone"/>
        <exclude body1="endoscope_third" body2="bone"/>
        <exclude body1="box_1" body2="bone"/>

<!--        <exclude body1="box_small1" body2="bone"/>
        <exclude body1="box_small2" body2="bone"/>
        <exclude body1="box_small3" body2="bone"/>
        <exclude body1="box_small4" body2="bone"/>-->


    </contact>

    <worldbody>
        <light directional="true" cutoff="4" exponent="20" diffuse="1 1 1" specular="0 0 0" pos="1 1 3" dir="-.5 -0.75 -1.5"/>
        <geom name='floor' material="floor_mat" pos='0 0 0' size='2.5 2.5 0.1'  type='plane' />

<!--        <body name="box_plane" childclass="panda" pos="0.7 0.3 0.48" euler='0 0 0'>
          <geom  friction="1.5 1.5 .1" size=".4 .4 .001"  type="box" rgba=".5 .55 .5 1" mass="0.01"/>
        </body>-->

        <geom pos="0.9 0.2 0.5" size=".15 .15 .001"  rgba=".5647 .933 .5647 1" type='box'/>


        <body name="box_1" pos="0.92 0.17 0.6" euler='0 0 0'>
          <freejoint/>
          <geom  friction="1 0.5 0.01" size=".02 .02 .02"  type="box" rgba="0.6 0.449 1 1" mass="1" />
        </body>

<!--        <body name="box_2" pos="0.92 0.23 0.6" euler='0 0 0'>
          <freejoint/>
          <geom  friction="1 0.5 0.0001" size=".02 .02 .02"  type="box" rgba="0.6 0.549 1 1" mass="2"/>
        </body>-->

<!--        <body name="box_small1" childclass="panda" pos="0.9 0.13 0.6" euler='0 0 0'>
          <freejoint/>
          <geom  friction="1 0.5 0.0001" size=".0005 .0005 .01"  type="box" rgba="0.2 0.749 1 1" mass="0.1"/>
        </body>
        <body name="box_small2" childclass="panda" pos="0.9 0.18 0.6" euler='0 0 0'>
          <freejoint/>
          <geom  friction="1 0.5 0.0001" size=".0005 .0005 .01"  type="box" rgba="0.6 0.749 0.4 1" mass="0.1"/>
        </body>
        <body name="box_small3" childclass="panda" pos="0.9 0.23 0.6" euler='0 0 0'>
          <freejoint/>
          <geom  friction="1 0.5 0.0001" size=".0005 .0005 .01"  type="box" rgba="0.6 0.149 1 1" mass="0.1"/>
        </body>
        <body name="box_small4" childclass="panda" pos="0.9 0.28 0.6" euler='0 0 0'>
          <freejoint/>
          <geom  friction="1 0.5 0.0001" size=".0005 .0005 .01"  type="box" rgba="0.1 0.749 1 1" mass="0.1"/>
        </body>-->


        <body name="bone" childclass="panda" pos="1.04 0.45 0.48" euler='0 -1.57 -1.57'>
             <geom class="panda_viz" mesh="bone_part_viz" rgba="0.6 0.749 1 1"/>
             <geom class="panda_col" mesh="bone_part_col" mass="10"/>
         </body>

         <body name="desk" childclass="panda" pos="1 0.2 0.48" euler='1.57 1.57 0'>
              <geom class="panda_viz" mesh="bed_viz" rgba="0.6 0.749 1 1"/>
              <geom class="panda_col" mesh="bed_col" mass="10"/>
          </body>

        <body name="base_0" childclass="panda" pos="-0.4 0.12 0" >
            <geom class="panda_viz" mesh="base_0_viz"/>
            <geom class="panda_col" mesh="base_0_col" mass="3.8"/>
            <body name="base_1"  pos="0.65742 0.044 1.815" euler='0 0 0.75'>
                <geom class="panda_viz" mesh="base_1_viz"/>
                <geom class="panda_col" mesh="base_1_col" mass="3.8"/>
            </body>
        </body>

        <body name="base_2_1" pos="0.3 0.45 1.7" euler='0 1.57 0'>
            <geom class="panda_viz" type="box" pos="0 0 0" euler='-2 0 0' size="0.07 0.07 0.2"/>
        </body>

        <body name="base_2_2" pos="0.03 0.33 1.7" euler='0 1.57 0'>
            <geom class="panda_viz" type="box" pos="0 0 0" euler='-2.4 0 0' size="0.07 0.07 0.25"/>
        </body>

        <body name="base_2_3" pos="0.29 -0.13 1.7" euler='0 1.57 0'>
            <geom class="panda_viz" type="box" pos="0 0 0" euler='2 0 0' size="0.07 0.07 0.2"/>
        </body>

        <body name="base_2_4" pos="0.1 0 1.7" euler='0 1.57 0'>
            <geom class="panda_viz" type="box" pos="0 0 0" euler='2 0 0' size="0.07 0.07 0.1"/>
        </body>

        <body name="base_3" childclass="panda" pos="0.25 -0.315 1.5" quat="-0.3 0 0 0.991665">
             <geom class="panda_viz" mesh="base_3_viz"/>
             <geom class="panda_col" mesh="base_3_col" mass="3.8"/>
             <geom class="panda_viz" type="box" pos="0 0 0.14" euler='0 0 0' size="0.07 0.07 0.14"/>
             <body name="base_4" pos="-0.055 0 -0.36518" quat="0.866025 0 0.5 0">
                 <geom class="panda_viz" mesh="base_4_viz"/>
                 <geom class="panda_col" mesh="base_4_col" mass="0.152"/>
                 <body name="roll1" pos="0 0 -0.15236273603" quat="1 0 0 0">
                     <joint name="roll1_joint" range="-3.14159 3.14159" class="panda_arm" damping="500"/>
                     <geom class="panda_viz" mesh="roll1_viz"/>
                     <geom class="panda_col" mesh="roll1_col" mass="0.394"/>
                     <body name="roll2" pos="0.1619 0 -0.11296" quat="0.991445 0 0.130526 0 ">
                         <joint name="roll2_joint" range="-3 3" class="panda_arm"/>
                         <geom class="panda_viz" mesh="roll2_viz"/>
                         <geom class="panda_col" mesh="roll2_col" mass="0.646"/>
                         <body name="para2" pos="0.06078 -0.0025 -0.27804" quat="0.664463 0.664463 0.241845 -0.241845 ">
                             <joint name="para2_joint" range="-3.14 3.14" class="panda_arm"/>
                             <geom class="panda_viz" mesh="para2_viz"/>
                             <geom class="panda_col" mesh="para2_col" mass="0.213"/>
                             <body name="para3" pos="-0.2 0 -0.0415" quat="0.5 0 0 0.866025 ">
                                 <joint name="para3_joint" range="-3.14 3.14" class="panda_arm"/>
                                 <geom class="panda_viz" mesh="para3_viz"/>
                                 <geom class="panda_col" mesh="para3_col" mass="0.329"/>
                                 <body name="slide" pos="-0.350 0 0.0305" quat="1 0 0 0">
                                     <joint name="slide_joint" range="-3.14 3.14" class="panda_arm"/>
                                     <geom class="panda_viz" mesh="slide_viz"/>
                                     <geom class="panda_col" mesh="slide_col" mass="1.256"/>
                                     <body name="instrument" pos="-0.1 0.08 0.0085" quat="0.5 0.5 -0.5 0.5">
                                         <joint name="instrument_joint" type="slide" range="-0.40 0.40" class="panda_arm"/>
                                         <geom class="panda_viz" mesh="instrument_viz"/>
                                         <geom class="panda_col" mesh="instrument_col" mass="0.19373"/>
                                         <body name="rotate" pos="0 0 0.3759" quat="1 0 0 0">
                                             <joint name="rotate_joint" range="-3.14 3.14" class="panda_forearm"/>
                                             <geom class="panda_viz" mesh="rotate_viz"/>
                                             <geom class="panda_col" mesh="rotate_col" mass="0.1"/>
                                             <body name="roll" pos="0 0 0" quat="3.2758e-05 0.707107 0.707107 3.2758e-05">
                                                 <joint name="roll_joint" axis="1 0 0" range="-3.14 3.14" class="panda_forearm"/>
                                                 <geom class="panda_viz" mesh="roll_viz"/>
                                                 <geom class="panda_col" mesh="roll_col" mass="0.1"/>
                                                 <body name="clip1" pos="0 0.0003 -0.0089" quat="0.707107 -0.707107 0 0">
                                                     <joint name="clip1_joint" range="-3.14 3.14" class="panda_finger"/>
                                                     <geom class="panda_viz" mesh="clip1_viz"/>
                                                     <geom class="panda_col" mesh="clip1_col" mass="0.1" />
                                                 </body>
                                                 <body name="clip2" pos="0 -0.0003 -0.0089" quat="3.2758e-05 3.2758e-05 0.707107 -0.707107 ">
                                                     <joint name="clip2_joint" range="-3.14 3.14" class="panda_finger"/>
                                                     <geom class="panda_viz" mesh="clip2_viz"/>
                                                     <geom class="panda_col" mesh="clip2_col" mass="0.1" />
                                                 </body>
                                             </body>
                                         </body>
                                     </body>
                                 </body>
                             </body>
                         </body>
                     </body>
                 </body>
             </body>
         </body>
         <body name="base_3_dual" childclass="panda" pos="0.18 0.6 1.5" quat="0.20 0 0 0.995415">
              <geom class="panda_viz" mesh="base_3_viz"/>
              <geom class="panda_col" mesh="base_3_col" mass="3.8"/>
              <geom class="panda_viz" type="box" pos="0 0 0.14" euler='0 0 0' size="0.07 0.07 0.14"/>

              <body name="base_4_dual" pos="-0.055 0 -0.36518" quat="0.866025 0 0.5 0">
                  <geom class="panda_viz" mesh="base_4_viz"/>
                  <geom class="panda_col" mesh="base_4_col" mass="0.152"/>
                  <body name="roll1_dual" pos="0 0 -0.15236273603" quat="1 0 0 0">
                      <joint name="roll1_joint_dual" range="-3.14159 3.14159" class="panda_arm" damping="500"/>
                      <geom class="panda_viz" mesh="roll1_viz"/>
                      <geom class="panda_col" mesh="roll1_col" mass="0.394"/>
                      <body name="roll2_dual" pos="0.1619 0 -0.11296" quat="0.991445 0 0.130526 0 ">
                          <joint name="roll2_joint_dual" range="-3 3" class="panda_arm"/>
                          <geom class="panda_viz" mesh="roll2_viz"/>
                          <geom class="panda_col" mesh="roll2_col" mass="0.646"/>
                          <body name="para2_dual" pos="0.06078 -0.0025 -0.27804" quat="0.664463 0.664463 0.241845 -0.241845 ">
                              <joint name="para2_joint_dual" range="-3.14 3.14" class="panda_arm"/>
                              <geom class="panda_viz" mesh="para2_viz"/>
                              <geom class="panda_col" mesh="para2_col" mass="0.213"/>
                              <body name="para3_dual" pos="-0.2 0 -0.0415" quat="0.5 0 0 0.866025 ">
                                  <joint name="para3_joint_dual" range="-3.14 3.14" class="panda_arm"/>
                                  <geom class="panda_viz" mesh="para3_viz"/>
                                  <geom class="panda_col" mesh="para3_col" mass="0.329"/>
                                  <body name="slide_dual" pos="-0.350 0 0.0305" quat="1 0 0 0">
                                      <joint name="slide_joint_dual" range="-3.14 3.14" class="panda_arm"/>
                                      <geom class="panda_viz" mesh="slide_viz"/>
                                      <geom class="panda_col" mesh="slide_col" mass="1.256"/>
                                      <body name="instrument_dual" pos="-0.1 0.08 0.0085" quat="0.5 0.5 -0.5 0.5">
                                          <joint name="instrument_joint_dual" type="slide" range="-0.40 0.40" class="panda_arm"/>
                                          <geom class="panda_viz" mesh="instrument_viz"/>
                                          <geom class="panda_col" mesh="instrument_col" mass="0.19373"/>
                                          <body name="rotate_dual" pos="0 0 0.3759" quat="1 0 0 0">
                                              <joint name="rotate_joint_dual" range="-3.14 3.14" class="panda_forearm"/>
                                              <geom class="panda_viz" mesh="rotate_viz"/>
                                              <geom class="panda_col" mesh="rotate_col" mass="0.1"/>
                                              <body name="roll_dual" pos="0 0 0" quat="3.2758e-05 0.707107 0.707107 3.2758e-05">
                                                  <joint name="roll_joint_dual" axis="1 0 0" range="-3.14 3.14" class="panda_forearm"/>
                                                  <geom class="panda_viz" mesh="roll_viz"/>
                                                  <geom class="panda_col" mesh="roll_col" mass="0.1"/>
                                                  <body name="clip1_dual" pos="0 0.0003 -0.0089" quat="0.707107 -0.707107 0 0">
                                                      <joint name="clip1_joint_dual" range="-3.14 3.14" class="panda_finger"/>
                                                      <geom class="panda_viz" mesh="clip1_viz"/>
                                                      <geom class="panda_col" mesh="clip1_col" mass="0.1" />
                                                  </body>
                                                  <body name="clip2_dual" pos="0 -0.0003 -0.0089" quat="3.2758e-05 3.2758e-05 0.707107 -0.707107 ">
                                                      <joint name="clip2_joint_dual" range="-3.14 3.14" class="panda_finger"/>
                                                      <geom class="panda_viz" mesh="clip2_viz"/>
                                                      <geom class="panda_col" mesh="clip2_col" mass="0.1" />
                                                  </body>
                                              </body>
                                          </body>
                                      </body>
                                  </body>
                              </body>
                          </body>
                      </body>
                  </body>
              </body>
          </body>
          <body name="base_3_third" childclass="panda" pos="0.04 -0.04 1.5" quat="-0.150 0 0 0.948985">
               <geom class="panda_viz" mesh="base_3_viz"/>
               <geom class="panda_col" mesh="base_3_col" mass="3.8"/>
               <geom class="panda_viz" type="box" pos="0 0 0.14" euler='0 0 0' size="0.07 0.07 0.14"/>
               <body name="base_4_third" pos="-0.055 0 -0.36518" quat="0.866025 0 0.5 0">
                   <geom class="panda_viz" mesh="base_4_viz"/>
                   <geom class="panda_col" mesh="base_4_col" mass="0.152"/>
                   <body name="roll1_third" pos="0 0 -0.15236273603" quat="1 0 0 0">
                       <joint name="roll1_joint_third" range="-3.14159 3.14159" class="panda_arm" damping="500"/>
                       <geom class="panda_viz" mesh="roll1_viz"/>
                       <geom class="panda_col" mesh="roll1_col" mass="0.394"/>
                       <body name="roll2_third" pos="0.1619 0 -0.11296" quat="0.991445 0 0.130526 0 ">
                           <joint name="roll2_joint_third" range="-3 3" class="panda_arm"/>
                           <geom class="panda_viz" mesh="roll2_viz"/>
                           <geom class="panda_col" mesh="roll2_col" mass="0.646"/>
                           <body name="para2_third" pos="0.06078 -0.0025 -0.27804" quat="0.664463 0.664463 0.241845 -0.241845 ">
                               <joint name="para2_joint_third" range="-3.14 3.14" class="panda_arm"/>
                               <geom class="panda_viz" mesh="para2_viz"/>
                               <geom class="panda_col" mesh="para2_col" mass="0.213"/>
                               <body name="para3_third" pos="-0.2 0 -0.0415" quat="0.5 0 0 0.866025 ">
                                   <joint name="para3_joint_third" range="-3.14 3.14" class="panda_arm"/>
                                   <geom class="panda_viz" mesh="para3_viz"/>
                                   <geom class="panda_col" mesh="para3_col" mass="0.329"/>
                                   <body name="slide_third" pos="-0.350 0 0.0305" quat="1 0 0 0">
                                       <joint name="slide_joint_third" range="-3.14 3.14" class="panda_arm"/>
                                       <geom class="panda_viz" mesh="slide_viz"/>
                                       <geom class="panda_col" mesh="slide_col" mass="1.256"/>
                                       <body name="endoscope_third" pos="-0.08 0.08 0.0085" euler='-1.5708 0 1.5708'>
                                           <joint name="instrument_joint_third" type="slide" range="-0.20 0.20" class="panda_forearm"/>
                                           <geom class="panda_viz" mesh="endoscope_viz"/>
                                           <geom class="panda_col" mesh="endoscope_col" mass="0.19373"/>
                                           <camera name="camera" mode="fixed"  pos="0.02 0.1 -0.1" euler='0 0 2.82' fovy = "45"/>
                                       </body>
                                   </body>
                               </body>
                           </body>
                       </body>
                   </body>
               </body>
           </body>

           <body name="base_3_fourth" childclass="panda" pos="-0.2 0.5 1.5" quat="0.15 0 0 0.995415">
                <geom class="panda_viz" mesh="base_3_viz"/>
                <geom class="panda_col" mesh="base_3_col" mass="3.8"/>
                <geom class="panda_viz" type="box" pos="0 0 0.14" euler='0 0 0' size="0.07 0.07 0.14"/>

                <body name="base_4_fourth" pos="-0.055 0 -0.36518" quat="0.866025 0 0.5 0">
                    <geom class="panda_viz" mesh="base_4_viz"/>
                    <geom class="panda_col" mesh="base_4_col" mass="0.152"/>
                    <body name="roll1_fourth" pos="0 0 -0.15236273603" quat="1 0 0 0">
                        <joint name="roll1_joint_fourth" range="-3.14159 3.14159" class="panda_arm" damping="500"/>
                        <geom class="panda_viz" mesh="roll1_viz"/>
                        <geom class="panda_col" mesh="roll1_col" mass="0.394"/>
                        <body name="roll2_fourth" pos="0.1619 0 -0.11296" quat="0.991445 0 0.130526 0 ">
                            <joint name="roll2_joint_fourth" range="-3 3" class="panda_arm"/>
                            <geom class="panda_viz" mesh="roll2_viz"/>
                            <geom class="panda_col" mesh="roll2_col" mass="0.646"/>
                            <body name="para2_fourth" pos="0.06078 -0.0025 -0.27804" quat="0.664463 0.664463 0.241845 -0.241845 ">
                                <joint name="para2_joint_fourth" range="-3.14 3.14" class="panda_arm"/>
                                <geom class="panda_viz" mesh="para2_viz"/>
                                <geom class="panda_col" mesh="para2_col" mass="0.213"/>
                                <body name="para3_fourth" pos="-0.2 0 -0.0415" quat="0.5 0 0 0.866025 ">
                                    <joint name="para3_joint_fourth" range="-3.14 3.14" class="panda_arm"/>
                                    <geom class="panda_viz" mesh="para3_viz"/>
                                    <geom class="panda_col" mesh="para3_col" mass="0.329"/>
                                    <body name="slide_fourth" pos="-0.350 0 0.0305" quat="1 0 0 0">
                                        <joint name="slide_joint_fourth" range="-3.14 3.14" class="panda_arm"/>
                                        <geom class="panda_viz" mesh="slide_viz"/>
                                        <geom class="panda_col" mesh="slide_col" mass="1.256"/>
                                        <body name="instrument_fourth" pos="-0.1 0.08 0.0085" quat="0.5 0.5 -0.5 0.5">
                                            <joint name="instrument_joint_fourth" type="slide" range="-0.20 0.20" class="panda_forearm"/>
                                            <geom class="panda_viz" mesh="instrument_viz"/>
                                            <geom class="panda_col" mesh="instrument_col" mass="0.19373"/>
                                            <body name="rotate_fourth" pos="0 0 0.3759" quat="1 0 0 0">
                                                <joint name="rotate_joint_fourth" range="-3.14 3.14" class="panda_forearm"/>
                                                <geom class="panda_viz" mesh="rotate_viz"/>
                                                <geom class="panda_col" mesh="rotate_col" mass="0.1"/>
                                                <body name="roll_fourth" pos="0 0 0" quat="3.2758e-05 0.707107 0.707107 3.2758e-05">
                                                    <joint name="roll_joint_fourth" axis="1 0 0" range="-3.14 3.14" class="panda_forearm"/>
                                                    <geom class="panda_viz" mesh="roll_viz"/>
                                                    <geom class="panda_col" mesh="roll_col" mass="0.1"/>
                                                    <body name="clip1_fourth" pos="0 0.0003 -0.0089" quat="0.707107 -0.707107 0 0">
                                                        <joint name="clip1_joint_fourth" range="-3.14 3.14" class="panda_finger"/>
                                                        <geom class="panda_viz" mesh="clip1_viz"/>
                                                        <geom class="panda_col" mesh="clip1_col" mass="0.1"/>
                                                    </body>
                                                    <body name="clip2_fourth" pos="0 -0.0003 -0.0089" quat="3.2758e-05 3.2758e-05 0.707107 -0.707107 ">
                                                        <joint name="clip2_joint_fourth" range="-3.14 3.14" class="panda_finger"/>
                                                        <geom class="panda_viz" mesh="clip2_viz"/>
                                                        <geom class="panda_col" mesh="clip2_col" mass="0.1"/>
                                                    </body>
                                                </body>
                                            </body>
                                        </body>
                                    </body>
                                </body>
                            </body>
                        </body>
                    </body>
                </body>
            </body>
    </worldbody>

    <equality>
        <joint name="para2_joint_to_para3_joint" joint1="para2_joint" joint2="para3_joint" polycoef="0 -1 0 0 0"/>
        <joint name="para3_joint_to_slide_joint" joint1="para2_joint" joint2="slide_joint" polycoef="0 1 0 0 0"/>
        <joint name="clip1_joint_to_clip2_joint" joint1="clip2_joint" joint2="clip1_joint" polycoef="0 1 0 0 0"/>

        <joint name="para2_joint_to_para3_joint_dual" joint1="para2_joint_dual" joint2="para3_joint_dual" polycoef="0 -1 0 0 0"/>
        <joint name="para3_joint_to_slide_joint_dual" joint1="para2_joint_dual" joint2="slide_joint_dual" polycoef="0 1 0 0 0"/>
        <joint name="clip1_joint_to_clip2_joint_dual" joint1="clip2_joint_dual" joint2="clip1_joint_dual" polycoef="0 1 0 0 0"/>

        <joint name="para2_joint_to_para3_joint_third" joint1="para2_joint_third" joint2="para3_joint_third" polycoef="0 -1 0 0 0"/>
        <joint name="para3_joint_to_slide_joint_third" joint1="para2_joint_third" joint2="slide_joint_third" polycoef="0 1 0 0 0"/>

        <joint name="para2_joint_to_para3_joint_fourth" joint1="para2_joint_fourth" joint2="para3_joint_fourth" polycoef="0 -1 0 0 0"/>
        <joint name="para3_joint_to_slide_joint_fourth" joint1="para2_joint_fourth" joint2="slide_joint_fourth" polycoef="0 1 0 0 0"/>

    </equality>

    <actuator>
        <position name="roll1_joint"      joint="roll1_joint"       kp="2000" forcerange="-87 87" ctrlrange="-2.9671 2.9671"/> <!-- velocity="2.1750" -->
        <position name="roll2_joint"      joint="roll2_joint"       kp="2000" forcerange="-87 87" ctrlrange="-2.8326 2.8326"/> <!-- velocity="2.1750" -->
        <position name="para2_joint"      joint="para2_joint"       kp="2000" forcerange="-87 87" ctrlrange="-2.9671 2.9671"/> <!-- velocity="2.1750" -->
        <position name="instrument_joint" joint="instrument_joint"  kp="2000"  forcerange="-87 87" ctrlrange="-0.40 0.40"/>     <!-- velocity="2.1750" -->
        <position name="rotate_joint"     joint="rotate_joint"      kp="30"  forcerange="-87 87" ctrlrange="-2.9671 2.9671"/> <!-- velocity="2.6100" -->
        <position name="roll_joint"       joint="roll_joint"        kp="30"  forcerange="-87 87" ctrlrange="-3.7525 2.1817"/> <!-- velocity="2.6100" -->
        <position name="clip1_joint"      joint="clip1_joint"       kp="30"  forcerange="-87 87" ctrlrange="-2.9671 2.9671"/> <!-- velocity="2.6100" -->

        <position name="roll1_joint_dual"      joint="roll1_joint_dual"       kp="2000" forcerange="-87 87" ctrlrange="-2.9671 2.9671"/> <!-- velocity="2.1750" -->
        <position name="roll2_joint_dual"      joint="roll2_joint_dual"       kp="2000" forcerange="-87 87" ctrlrange="-2.8326 2.8326"/> <!-- velocity="2.1750" -->
        <position name="para2_joint_dual"      joint="para2_joint_dual"       kp="2000" forcerange="-87 87" ctrlrange="-2.9671 2.9671"/> <!-- velocity="2.1750" -->
        <position name="instrument_joint_dual" joint="instrument_joint_dual"  kp="2000"  forcerange="-87 87" ctrlrange="-0.40 0.40"/>     <!-- velocity="2.1750" -->
        <position name="rotate_joint_dual"     joint="rotate_joint_dual"      kp="30"  forcerange="-87 87" ctrlrange="-2.9671 2.9671"/> <!-- velocity="2.6100" -->
        <position name="roll_joint_dual"       joint="roll_joint_dual"        kp="30"  forcerange="-87 87" ctrlrange="-3.7525 2.1817"/> <!-- velocity="2.6100" -->
        <position name="clip1_joint_dual"      joint="clip1_joint_dual"       kp="30"  forcerange="-87 87" ctrlrange="-2.9671 2.9671"/> <!-- velocity="2.6100" -->

        <position name="roll1_joint_third"      joint="roll1_joint_third"       kp="870" forcerange="-87 87" ctrlrange="-2.9671 2.9671"/> <!-- velocity="2.1750" -->
        <position name="roll2_joint_third"      joint="roll2_joint_third"       kp="870" forcerange="-87 87" ctrlrange="-2.8326 2.8326"/> <!-- velocity="2.1750" -->
        <position name="para2_joint_third"      joint="para2_joint_third"       kp="870" forcerange="-87 87" ctrlrange="-2.9671 2.9671"/> <!-- velocity="2.1750" -->
        <position name="instrument_joint_third" joint="instrument_joint_third"  kp="100"  forcerange="-87 87" ctrlrange="-2.20 2.20"/>     <!-- velocity="2.1750" -->

        <position name="roll1_joint_fourth"      joint="roll1_joint_fourth"       kp="870" forcerange="-87 87" ctrlrange="-2.9671 2.9671"/> <!-- velocity="2.1750" -->
        <position name="roll2_joint_fourth"      joint="roll2_joint_fourth"       kp="870" forcerange="-87 87" ctrlrange="-2.8326 2.8326"/> <!-- velocity="2.1750" -->
        <position name="para2_joint_fourth"      joint="para2_joint_fourth"       kp="870" forcerange="-87 87" ctrlrange="-2.9671 2.9671"/> <!-- velocity="2.1750" -->
        <position name="instrument_joint_fourth" joint="instrument_joint_fourth"  kp="100"  forcerange="-87 87" ctrlrange="-2.20 2.20"/>     <!-- velocity="2.1750" -->
        <position name="rotate_joint_fourth"     joint="rotate_joint_fourth"      kp="20"  forcerange="-12 12" ctrlrange="-2.9671 2.9671"/> <!-- velocity="2.6100" -->
        <position name="roll_joint_fourth"       joint="roll_joint_fourth"        kp="20"  forcerange="-12 12" ctrlrange="-3.7525 2.1817"/> <!-- velocity="2.6100" -->
        <position name="clip1_joint_fourth"      joint="clip1_joint_fourth"       kp="20"  forcerange="-12 12" ctrlrange="-2.9671 2.9671"/> <!-- velocity="2.6100" -->

    </actuator>

    <sensor>
        <jointpos name="roll2_joint"      joint="roll2_joint"/>
    </sensor>





</mujoco>























































